2025-03-05 11:35:52,442 INFO    StreamThr :64231 [internal.py:wandb_internal():85] W&B internal server running at pid: 64231, started at: 2025-03-05 11:35:52.441904
2025-03-05 11:35:52,443 DEBUG   HandlerThread:64231 [handler.py:handle_request():158] handle_request: status
2025-03-05 11:35:52,449 INFO    WriterThread:64231 [datastore.py:open_for_write():87] open: ./wandb/run-20250305_113552-tp27htmq/run-tp27htmq.wandb
2025-03-05 11:35:52,449 DEBUG   SenderThread:64231 [sender.py:send():379] send: header
2025-03-05 11:35:52,484 DEBUG   SenderThread:64231 [sender.py:send():379] send: run
2025-03-05 11:35:52,485 INFO    SenderThread:64231 [sender.py:_setup_resume():749] checking resume status for None/LSTM-Prediction/tp27htmq
2025-03-05 11:35:52,805 INFO    SenderThread:64231 [dir_watcher.py:__init__():211] watching files in: ./wandb/run-20250305_113552-tp27htmq/files
2025-03-05 11:35:52,806 INFO    SenderThread:64231 [sender.py:_start_run_threads():1188] run started: tp27htmq with start time 1741196152.442533
2025-03-05 11:35:52,816 DEBUG   HandlerThread:64231 [handler.py:handle_request():158] handle_request: check_version
2025-03-05 11:35:52,816 DEBUG   SenderThread:64231 [sender.py:send_request():406] send_request: check_version
2025-03-05 11:35:53,013 DEBUG   HandlerThread:64231 [handler.py:handle_request():158] handle_request: run_start
2025-03-05 11:35:53,029 DEBUG   HandlerThread:64231 [system_info.py:__init__():26] System info init
2025-03-05 11:35:53,029 DEBUG   HandlerThread:64231 [system_info.py:__init__():41] System info init done
2025-03-05 11:35:53,029 INFO    HandlerThread:64231 [system_monitor.py:start():194] Starting system monitor
2025-03-05 11:35:53,030 INFO    SystemMonitor:64231 [system_monitor.py:_start():158] Starting system asset monitoring threads
2025-03-05 11:35:53,030 INFO    HandlerThread:64231 [system_monitor.py:probe():214] Collecting system info
2025-03-05 11:35:53,031 INFO    SystemMonitor:64231 [interfaces.py:start():188] Started cpu monitoring
2025-03-05 11:35:53,033 INFO    SystemMonitor:64231 [interfaces.py:start():188] Started disk monitoring
2025-03-05 11:35:53,036 INFO    SystemMonitor:64231 [interfaces.py:start():188] Started gpuapple monitoring
2025-03-05 11:35:53,036 ERROR   HandlerThread:64231 [gpu_apple.py:probe():176] GPU stats error: [Errno 2] No such file or directory: '/Users/luozisheng/miniconda3/envs/seg/lib/python3.9/site-packages/wandb/bin/apple_gpu_stats'
Traceback (most recent call last):
  File "/Users/luozisheng/miniconda3/envs/seg/lib/python3.9/site-packages/wandb/sdk/internal/system/assets/gpu_apple.py", line 164, in probe
    subprocess.check_output(command, universal_newlines=True)
  File "/Users/luozisheng/miniconda3/envs/seg/lib/python3.9/subprocess.py", line 424, in check_output
    return run(*popenargs, stdout=PIPE, timeout=timeout, check=True,
  File "/Users/luozisheng/miniconda3/envs/seg/lib/python3.9/subprocess.py", line 505, in run
    with Popen(*popenargs, **kwargs) as process:
  File "/Users/luozisheng/miniconda3/envs/seg/lib/python3.9/subprocess.py", line 951, in __init__
    self._execute_child(args, executable, preexec_fn, close_fds,
  File "/Users/luozisheng/miniconda3/envs/seg/lib/python3.9/subprocess.py", line 1837, in _execute_child
    raise child_exception_type(errno_num, err_msg, err_filename)
FileNotFoundError: [Errno 2] No such file or directory: '/Users/luozisheng/miniconda3/envs/seg/lib/python3.9/site-packages/wandb/bin/apple_gpu_stats'
2025-03-05 11:35:53,039 ERROR   gpuapple  :64231 [gpu_apple.py:sample():110] GPU stats error: [Errno 2] No such file or directory: '/Users/luozisheng/miniconda3/envs/seg/lib/python3.9/site-packages/wandb/bin/apple_gpu_stats'
Traceback (most recent call last):
  File "/Users/luozisheng/miniconda3/envs/seg/lib/python3.9/site-packages/wandb/sdk/internal/system/assets/gpu_apple.py", line 64, in sample
    subprocess.check_output(command, universal_newlines=True)
  File "/Users/luozisheng/miniconda3/envs/seg/lib/python3.9/subprocess.py", line 424, in check_output
    return run(*popenargs, stdout=PIPE, timeout=timeout, check=True,
  File "/Users/luozisheng/miniconda3/envs/seg/lib/python3.9/subprocess.py", line 505, in run
    with Popen(*popenargs, **kwargs) as process:
  File "/Users/luozisheng/miniconda3/envs/seg/lib/python3.9/subprocess.py", line 951, in __init__
    self._execute_child(args, executable, preexec_fn, close_fds,
  File "/Users/luozisheng/miniconda3/envs/seg/lib/python3.9/subprocess.py", line 1837, in _execute_child
    raise child_exception_type(errno_num, err_msg, err_filename)
FileNotFoundError: [Errno 2] No such file or directory: '/Users/luozisheng/miniconda3/envs/seg/lib/python3.9/site-packages/wandb/bin/apple_gpu_stats'
2025-03-05 11:35:53,040 INFO    SystemMonitor:64231 [interfaces.py:start():188] Started memory monitoring
2025-03-05 11:35:53,041 DEBUG   HandlerThread:64231 [system_info.py:probe():152] Probing system
2025-03-05 11:35:53,042 INFO    SystemMonitor:64231 [interfaces.py:start():188] Started network monitoring
2025-03-05 11:35:53,045 DEBUG   HandlerThread:64231 [system_info.py:_probe_git():137] Probing git
2025-03-05 11:35:53,070 DEBUG   HandlerThread:64231 [system_info.py:_probe_git():145] Probing git done
2025-03-05 11:35:53,071 DEBUG   HandlerThread:64231 [system_info.py:probe():200] Probing system done
2025-03-05 11:35:53,071 DEBUG   HandlerThread:64231 [system_monitor.py:probe():223] {'os': 'macOS-14.4.1-arm64-arm-64bit', 'python': '3.9.19', 'heartbeatAt': '2025-03-05T17:35:53.042420', 'startedAt': '2025-03-05T17:35:52.430824', 'docker': None, 'cuda': None, 'args': (), 'state': 'running', 'program': '/Users/luozisheng/Documents/Zhu_lab/TimeSeriesPrediction/main.py', 'codePathLocal': 'main.py', 'codePath': 'main.py', 'git': {'remote': 'https://github.com/AaronLuo-ai/TimeSeriesSegmentation.git', 'commit': '28dfbe0ba0f264cd994c385e504cdd6f64adbc73'}, 'email': '89952488+AaR0nLu0@users.noreply.github.com', 'root': '/Users/luozisheng/Documents/Zhu_lab/TimeSeriesPrediction', 'host': 'MacBook-Pro-10.local', 'username': 'luozisheng', 'executable': '/Users/luozisheng/miniconda3/envs/seg/bin/python', 'cpu_count': 10, 'cpu_count_logical': 10, 'disk': {'/': {'total': 926.3517189025879, 'used': 427.28931427001953}}, 'gpuapple': {'type': 'arm', 'vendor': 'Apple'}, 'memory': {'total': 16.0}}
2025-03-05 11:35:53,071 INFO    HandlerThread:64231 [system_monitor.py:probe():224] Finished collecting system info
2025-03-05 11:35:53,071 INFO    HandlerThread:64231 [system_monitor.py:probe():227] Publishing system info
2025-03-05 11:35:53,071 DEBUG   HandlerThread:64231 [system_info.py:_save_conda():209] Saving list of conda packages installed into the current environment
2025-03-05 11:35:53,811 INFO    Thread-12 :64231 [dir_watcher.py:_on_file_created():271] file/dir created: ./wandb/run-20250305_113552-tp27htmq/files/conda-environment.yaml
2025-03-05 11:35:55,049 ERROR   gpuapple  :64231 [gpu_apple.py:sample():110] GPU stats error: [Errno 2] No such file or directory: '/Users/luozisheng/miniconda3/envs/seg/lib/python3.9/site-packages/wandb/bin/apple_gpu_stats'
Traceback (most recent call last):
  File "/Users/luozisheng/miniconda3/envs/seg/lib/python3.9/site-packages/wandb/sdk/internal/system/assets/gpu_apple.py", line 64, in sample
    subprocess.check_output(command, universal_newlines=True)
  File "/Users/luozisheng/miniconda3/envs/seg/lib/python3.9/subprocess.py", line 424, in check_output
    return run(*popenargs, stdout=PIPE, timeout=timeout, check=True,
  File "/Users/luozisheng/miniconda3/envs/seg/lib/python3.9/subprocess.py", line 505, in run
    with Popen(*popenargs, **kwargs) as process:
  File "/Users/luozisheng/miniconda3/envs/seg/lib/python3.9/subprocess.py", line 951, in __init__
    self._execute_child(args, executable, preexec_fn, close_fds,
  File "/Users/luozisheng/miniconda3/envs/seg/lib/python3.9/subprocess.py", line 1837, in _execute_child
    raise child_exception_type(errno_num, err_msg, err_filename)
FileNotFoundError: [Errno 2] No such file or directory: '/Users/luozisheng/miniconda3/envs/seg/lib/python3.9/site-packages/wandb/bin/apple_gpu_stats'
2025-03-05 11:35:55,820 INFO    Thread-12 :64231 [dir_watcher.py:_on_file_modified():288] file/dir modified: ./wandb/run-20250305_113552-tp27htmq/files/conda-environment.yaml
2025-03-05 11:35:55,907 DEBUG   HandlerThread:64231 [system_info.py:_save_conda():224] Saving conda packages done
2025-03-05 11:35:55,908 INFO    HandlerThread:64231 [system_monitor.py:probe():229] Finished publishing system info
2025-03-05 11:35:55,921 DEBUG   SenderThread:64231 [sender.py:send():379] send: files
2025-03-05 11:35:55,921 INFO    SenderThread:64231 [sender.py:_save_file():1454] saving file wandb-metadata.json with policy now
2025-03-05 11:35:56,038 DEBUG   HandlerThread:64231 [handler.py:handle_request():158] handle_request: python_packages
2025-03-05 11:35:56,038 DEBUG   SenderThread:64231 [sender.py:send_request():406] send_request: python_packages
2025-03-05 11:35:56,039 DEBUG   HandlerThread:64231 [handler.py:handle_request():158] handle_request: internal_messages
2025-03-05 11:35:56,039 DEBUG   HandlerThread:64231 [handler.py:handle_request():158] handle_request: stop_status
2025-03-05 11:35:56,039 DEBUG   SenderThread:64231 [sender.py:send():379] send: telemetry
2025-03-05 11:35:56,039 DEBUG   SenderThread:64231 [sender.py:send_request():406] send_request: stop_status
2025-03-05 11:35:56,201 DEBUG   SenderThread:64231 [sender.py:send():379] send: telemetry
2025-03-05 11:35:56,201 DEBUG   SenderThread:64231 [sender.py:send():379] send: metric
2025-03-05 11:35:56,201 DEBUG   SenderThread:64231 [sender.py:send():379] send: telemetry
2025-03-05 11:35:56,201 DEBUG   SenderThread:64231 [sender.py:send():379] send: metric
2025-03-05 11:35:56,201 WARNING SenderThread:64231 [sender.py:send_metric():1405] Seen metric with glob (shouldn't happen)
2025-03-05 11:35:56,264 DEBUG   SenderThread:64231 [sender.py:send():379] send: config
2025-03-05 11:35:56,638 INFO    wandb-upload_0:64231 [upload_job.py:push():130] Uploaded file /var/folders/_3/r8lsqq9n4692d4qbqm6prhmw0000gn/T/tmpf5x60ox7wandb/l9bm3oja-wandb-metadata.json
2025-03-05 11:35:56,825 INFO    Thread-12 :64231 [dir_watcher.py:_on_file_created():271] file/dir created: ./wandb/run-20250305_113552-tp27htmq/files/output.log
2025-03-05 11:35:56,825 INFO    Thread-12 :64231 [dir_watcher.py:_on_file_created():271] file/dir created: ./wandb/run-20250305_113552-tp27htmq/files/requirements.txt
2025-03-05 11:35:56,826 INFO    Thread-12 :64231 [dir_watcher.py:_on_file_created():271] file/dir created: ./wandb/run-20250305_113552-tp27htmq/files/wandb-metadata.json
2025-03-05 11:35:57,040 DEBUG   HandlerThread:64231 [handler.py:handle_request():158] handle_request: internal_messages
2025-03-05 11:35:57,057 ERROR   gpuapple  :64231 [gpu_apple.py:sample():110] GPU stats error: [Errno 2] No such file or directory: '/Users/luozisheng/miniconda3/envs/seg/lib/python3.9/site-packages/wandb/bin/apple_gpu_stats'
Traceback (most recent call last):
  File "/Users/luozisheng/miniconda3/envs/seg/lib/python3.9/site-packages/wandb/sdk/internal/system/assets/gpu_apple.py", line 64, in sample
    subprocess.check_output(command, universal_newlines=True)
  File "/Users/luozisheng/miniconda3/envs/seg/lib/python3.9/subprocess.py", line 424, in check_output
    return run(*popenargs, stdout=PIPE, timeout=timeout, check=True,
  File "/Users/luozisheng/miniconda3/envs/seg/lib/python3.9/subprocess.py", line 505, in run
    with Popen(*popenargs, **kwargs) as process:
  File "/Users/luozisheng/miniconda3/envs/seg/lib/python3.9/subprocess.py", line 951, in __init__
    self._execute_child(args, executable, preexec_fn, close_fds,
  File "/Users/luozisheng/miniconda3/envs/seg/lib/python3.9/subprocess.py", line 1837, in _execute_child
    raise child_exception_type(errno_num, err_msg, err_filename)
FileNotFoundError: [Errno 2] No such file or directory: '/Users/luozisheng/miniconda3/envs/seg/lib/python3.9/site-packages/wandb/bin/apple_gpu_stats'
2025-03-05 11:35:58,045 DEBUG   HandlerThread:64231 [handler.py:handle_request():158] handle_request: internal_messages
2025-03-05 11:35:58,274 DEBUG   HandlerThread:64231 [handler.py:handle_request():158] handle_request: status_report
2025-03-05 11:35:58,829 INFO    Thread-12 :64231 [dir_watcher.py:_on_file_modified():288] file/dir modified: ./wandb/run-20250305_113552-tp27htmq/files/output.log
2025-03-05 11:35:59,050 DEBUG   HandlerThread:64231 [handler.py:handle_request():158] handle_request: internal_messages
2025-03-05 11:35:59,065 ERROR   gpuapple  :64231 [gpu_apple.py:sample():110] GPU stats error: [Errno 2] No such file or directory: '/Users/luozisheng/miniconda3/envs/seg/lib/python3.9/site-packages/wandb/bin/apple_gpu_stats'
Traceback (most recent call last):
  File "/Users/luozisheng/miniconda3/envs/seg/lib/python3.9/site-packages/wandb/sdk/internal/system/assets/gpu_apple.py", line 64, in sample
    subprocess.check_output(command, universal_newlines=True)
  File "/Users/luozisheng/miniconda3/envs/seg/lib/python3.9/subprocess.py", line 424, in check_output
    return run(*popenargs, stdout=PIPE, timeout=timeout, check=True,
  File "/Users/luozisheng/miniconda3/envs/seg/lib/python3.9/subprocess.py", line 505, in run
    with Popen(*popenargs, **kwargs) as process:
  File "/Users/luozisheng/miniconda3/envs/seg/lib/python3.9/subprocess.py", line 951, in __init__
    self._execute_child(args, executable, preexec_fn, close_fds,
  File "/Users/luozisheng/miniconda3/envs/seg/lib/python3.9/subprocess.py", line 1837, in _execute_child
    raise child_exception_type(errno_num, err_msg, err_filename)
FileNotFoundError: [Errno 2] No such file or directory: '/Users/luozisheng/miniconda3/envs/seg/lib/python3.9/site-packages/wandb/bin/apple_gpu_stats'
2025-03-05 11:36:00,051 DEBUG   HandlerThread:64231 [handler.py:handle_request():158] handle_request: internal_messages
2025-03-05 11:36:01,071 ERROR   gpuapple  :64231 [gpu_apple.py:sample():110] GPU stats error: [Errno 2] No such file or directory: '/Users/luozisheng/miniconda3/envs/seg/lib/python3.9/site-packages/wandb/bin/apple_gpu_stats'
Traceback (most recent call last):
  File "/Users/luozisheng/miniconda3/envs/seg/lib/python3.9/site-packages/wandb/sdk/internal/system/assets/gpu_apple.py", line 64, in sample
    subprocess.check_output(command, universal_newlines=True)
  File "/Users/luozisheng/miniconda3/envs/seg/lib/python3.9/subprocess.py", line 424, in check_output
    return run(*popenargs, stdout=PIPE, timeout=timeout, check=True,
  File "/Users/luozisheng/miniconda3/envs/seg/lib/python3.9/subprocess.py", line 505, in run
    with Popen(*popenargs, **kwargs) as process:
  File "/Users/luozisheng/miniconda3/envs/seg/lib/python3.9/subprocess.py", line 951, in __init__
    self._execute_child(args, executable, preexec_fn, close_fds,
  File "/Users/luozisheng/miniconda3/envs/seg/lib/python3.9/subprocess.py", line 1837, in _execute_child
    raise child_exception_type(errno_num, err_msg, err_filename)
FileNotFoundError: [Errno 2] No such file or directory: '/Users/luozisheng/miniconda3/envs/seg/lib/python3.9/site-packages/wandb/bin/apple_gpu_stats'
2025-03-05 11:36:01,256 DEBUG   HandlerThread:64231 [handler.py:handle_request():158] handle_request: internal_messages
2025-03-05 11:36:02,245 DEBUG   HandlerThread:64231 [handler.py:handle_request():158] handle_request: internal_messages
2025-03-05 11:36:03,080 ERROR   gpuapple  :64231 [gpu_apple.py:sample():110] GPU stats error: [Errno 2] No such file or directory: '/Users/luozisheng/miniconda3/envs/seg/lib/python3.9/site-packages/wandb/bin/apple_gpu_stats'
Traceback (most recent call last):
  File "/Users/luozisheng/miniconda3/envs/seg/lib/python3.9/site-packages/wandb/sdk/internal/system/assets/gpu_apple.py", line 64, in sample
    subprocess.check_output(command, universal_newlines=True)
  File "/Users/luozisheng/miniconda3/envs/seg/lib/python3.9/subprocess.py", line 424, in check_output
    return run(*popenargs, stdout=PIPE, timeout=timeout, check=True,
  File "/Users/luozisheng/miniconda3/envs/seg/lib/python3.9/subprocess.py", line 505, in run
    with Popen(*popenargs, **kwargs) as process:
  File "/Users/luozisheng/miniconda3/envs/seg/lib/python3.9/subprocess.py", line 951, in __init__
    self._execute_child(args, executable, preexec_fn, close_fds,
  File "/Users/luozisheng/miniconda3/envs/seg/lib/python3.9/subprocess.py", line 1837, in _execute_child
    raise child_exception_type(errno_num, err_msg, err_filename)
FileNotFoundError: [Errno 2] No such file or directory: '/Users/luozisheng/miniconda3/envs/seg/lib/python3.9/site-packages/wandb/bin/apple_gpu_stats'
2025-03-05 11:36:03,248 DEBUG   HandlerThread:64231 [handler.py:handle_request():158] handle_request: internal_messages
2025-03-05 11:36:04,250 DEBUG   HandlerThread:64231 [handler.py:handle_request():158] handle_request: internal_messages
2025-03-05 11:36:04,251 DEBUG   HandlerThread:64231 [handler.py:handle_request():158] handle_request: status_report
2025-03-05 11:36:05,094 ERROR   gpuapple  :64231 [gpu_apple.py:sample():110] GPU stats error: [Errno 2] No such file or directory: '/Users/luozisheng/miniconda3/envs/seg/lib/python3.9/site-packages/wandb/bin/apple_gpu_stats'
Traceback (most recent call last):
  File "/Users/luozisheng/miniconda3/envs/seg/lib/python3.9/site-packages/wandb/sdk/internal/system/assets/gpu_apple.py", line 64, in sample
    subprocess.check_output(command, universal_newlines=True)
  File "/Users/luozisheng/miniconda3/envs/seg/lib/python3.9/subprocess.py", line 424, in check_output
    return run(*popenargs, stdout=PIPE, timeout=timeout, check=True,
  File "/Users/luozisheng/miniconda3/envs/seg/lib/python3.9/subprocess.py", line 505, in run
    with Popen(*popenargs, **kwargs) as process:
  File "/Users/luozisheng/miniconda3/envs/seg/lib/python3.9/subprocess.py", line 951, in __init__
    self._execute_child(args, executable, preexec_fn, close_fds,
  File "/Users/luozisheng/miniconda3/envs/seg/lib/python3.9/subprocess.py", line 1837, in _execute_child
    raise child_exception_type(errno_num, err_msg, err_filename)
FileNotFoundError: [Errno 2] No such file or directory: '/Users/luozisheng/miniconda3/envs/seg/lib/python3.9/site-packages/wandb/bin/apple_gpu_stats'
2025-03-05 11:36:05,256 DEBUG   HandlerThread:64231 [handler.py:handle_request():158] handle_request: internal_messages
2025-03-05 11:36:06,260 DEBUG   HandlerThread:64231 [handler.py:handle_request():158] handle_request: internal_messages
2025-03-05 11:36:07,101 ERROR   gpuapple  :64231 [gpu_apple.py:sample():110] GPU stats error: [Errno 2] No such file or directory: '/Users/luozisheng/miniconda3/envs/seg/lib/python3.9/site-packages/wandb/bin/apple_gpu_stats'
Traceback (most recent call last):
  File "/Users/luozisheng/miniconda3/envs/seg/lib/python3.9/site-packages/wandb/sdk/internal/system/assets/gpu_apple.py", line 64, in sample
    subprocess.check_output(command, universal_newlines=True)
  File "/Users/luozisheng/miniconda3/envs/seg/lib/python3.9/subprocess.py", line 424, in check_output
    return run(*popenargs, stdout=PIPE, timeout=timeout, check=True,
  File "/Users/luozisheng/miniconda3/envs/seg/lib/python3.9/subprocess.py", line 505, in run
    with Popen(*popenargs, **kwargs) as process:
  File "/Users/luozisheng/miniconda3/envs/seg/lib/python3.9/subprocess.py", line 951, in __init__
    self._execute_child(args, executable, preexec_fn, close_fds,
  File "/Users/luozisheng/miniconda3/envs/seg/lib/python3.9/subprocess.py", line 1837, in _execute_child
    raise child_exception_type(errno_num, err_msg, err_filename)
FileNotFoundError: [Errno 2] No such file or directory: '/Users/luozisheng/miniconda3/envs/seg/lib/python3.9/site-packages/wandb/bin/apple_gpu_stats'
2025-03-05 11:36:07,265 DEBUG   HandlerThread:64231 [handler.py:handle_request():158] handle_request: internal_messages
2025-03-05 11:36:08,267 DEBUG   HandlerThread:64231 [handler.py:handle_request():158] handle_request: internal_messages
2025-03-05 11:36:09,109 ERROR   gpuapple  :64231 [gpu_apple.py:sample():110] GPU stats error: [Errno 2] No such file or directory: '/Users/luozisheng/miniconda3/envs/seg/lib/python3.9/site-packages/wandb/bin/apple_gpu_stats'
Traceback (most recent call last):
  File "/Users/luozisheng/miniconda3/envs/seg/lib/python3.9/site-packages/wandb/sdk/internal/system/assets/gpu_apple.py", line 64, in sample
    subprocess.check_output(command, universal_newlines=True)
  File "/Users/luozisheng/miniconda3/envs/seg/lib/python3.9/subprocess.py", line 424, in check_output
    return run(*popenargs, stdout=PIPE, timeout=timeout, check=True,
  File "/Users/luozisheng/miniconda3/envs/seg/lib/python3.9/subprocess.py", line 505, in run
    with Popen(*popenargs, **kwargs) as process:
  File "/Users/luozisheng/miniconda3/envs/seg/lib/python3.9/subprocess.py", line 951, in __init__
    self._execute_child(args, executable, preexec_fn, close_fds,
  File "/Users/luozisheng/miniconda3/envs/seg/lib/python3.9/subprocess.py", line 1837, in _execute_child
    raise child_exception_type(errno_num, err_msg, err_filename)
FileNotFoundError: [Errno 2] No such file or directory: '/Users/luozisheng/miniconda3/envs/seg/lib/python3.9/site-packages/wandb/bin/apple_gpu_stats'
2025-03-05 11:36:09,272 DEBUG   HandlerThread:64231 [handler.py:handle_request():158] handle_request: internal_messages
2025-03-05 11:36:10,255 DEBUG   HandlerThread:64231 [handler.py:handle_request():158] handle_request: status_report
2025-03-05 11:36:10,274 DEBUG   HandlerThread:64231 [handler.py:handle_request():158] handle_request: internal_messages
2025-03-05 11:36:11,043 DEBUG   HandlerThread:64231 [handler.py:handle_request():158] handle_request: stop_status
2025-03-05 11:36:11,043 DEBUG   SenderThread:64231 [sender.py:send_request():406] send_request: stop_status
2025-03-05 11:36:11,117 ERROR   gpuapple  :64231 [gpu_apple.py:sample():110] GPU stats error: [Errno 2] No such file or directory: '/Users/luozisheng/miniconda3/envs/seg/lib/python3.9/site-packages/wandb/bin/apple_gpu_stats'
Traceback (most recent call last):
  File "/Users/luozisheng/miniconda3/envs/seg/lib/python3.9/site-packages/wandb/sdk/internal/system/assets/gpu_apple.py", line 64, in sample
    subprocess.check_output(command, universal_newlines=True)
  File "/Users/luozisheng/miniconda3/envs/seg/lib/python3.9/subprocess.py", line 424, in check_output
    return run(*popenargs, stdout=PIPE, timeout=timeout, check=True,
  File "/Users/luozisheng/miniconda3/envs/seg/lib/python3.9/subprocess.py", line 505, in run
    with Popen(*popenargs, **kwargs) as process:
  File "/Users/luozisheng/miniconda3/envs/seg/lib/python3.9/subprocess.py", line 951, in __init__
    self._execute_child(args, executable, preexec_fn, close_fds,
  File "/Users/luozisheng/miniconda3/envs/seg/lib/python3.9/subprocess.py", line 1837, in _execute_child
    raise child_exception_type(errno_num, err_msg, err_filename)
FileNotFoundError: [Errno 2] No such file or directory: '/Users/luozisheng/miniconda3/envs/seg/lib/python3.9/site-packages/wandb/bin/apple_gpu_stats'
2025-03-05 11:36:11,279 DEBUG   HandlerThread:64231 [handler.py:handle_request():158] handle_request: internal_messages
2025-03-05 11:36:12,284 DEBUG   HandlerThread:64231 [handler.py:handle_request():158] handle_request: internal_messages
2025-03-05 11:36:12,877 INFO    Thread-12 :64231 [dir_watcher.py:_on_file_modified():288] file/dir modified: ./wandb/run-20250305_113552-tp27htmq/files/output.log
2025-03-05 11:36:13,126 ERROR   gpuapple  :64231 [gpu_apple.py:sample():110] GPU stats error: [Errno 2] No such file or directory: '/Users/luozisheng/miniconda3/envs/seg/lib/python3.9/site-packages/wandb/bin/apple_gpu_stats'
Traceback (most recent call last):
  File "/Users/luozisheng/miniconda3/envs/seg/lib/python3.9/site-packages/wandb/sdk/internal/system/assets/gpu_apple.py", line 64, in sample
    subprocess.check_output(command, universal_newlines=True)
  File "/Users/luozisheng/miniconda3/envs/seg/lib/python3.9/subprocess.py", line 424, in check_output
    return run(*popenargs, stdout=PIPE, timeout=timeout, check=True,
  File "/Users/luozisheng/miniconda3/envs/seg/lib/python3.9/subprocess.py", line 505, in run
    with Popen(*popenargs, **kwargs) as process:
  File "/Users/luozisheng/miniconda3/envs/seg/lib/python3.9/subprocess.py", line 951, in __init__
    self._execute_child(args, executable, preexec_fn, close_fds,
  File "/Users/luozisheng/miniconda3/envs/seg/lib/python3.9/subprocess.py", line 1837, in _execute_child
    raise child_exception_type(errno_num, err_msg, err_filename)
FileNotFoundError: [Errno 2] No such file or directory: '/Users/luozisheng/miniconda3/envs/seg/lib/python3.9/site-packages/wandb/bin/apple_gpu_stats'
2025-03-05 11:36:13,288 DEBUG   HandlerThread:64231 [handler.py:handle_request():158] handle_request: internal_messages
2025-03-05 11:36:13,883 INFO    Thread-12 :64231 [dir_watcher.py:_on_file_modified():288] file/dir modified: ./wandb/run-20250305_113552-tp27htmq/files/output.log
2025-03-05 11:36:14,294 DEBUG   HandlerThread:64231 [handler.py:handle_request():158] handle_request: internal_messages
2025-03-05 11:36:15,135 ERROR   gpuapple  :64231 [gpu_apple.py:sample():110] GPU stats error: [Errno 2] No such file or directory: '/Users/luozisheng/miniconda3/envs/seg/lib/python3.9/site-packages/wandb/bin/apple_gpu_stats'
Traceback (most recent call last):
  File "/Users/luozisheng/miniconda3/envs/seg/lib/python3.9/site-packages/wandb/sdk/internal/system/assets/gpu_apple.py", line 64, in sample
    subprocess.check_output(command, universal_newlines=True)
  File "/Users/luozisheng/miniconda3/envs/seg/lib/python3.9/subprocess.py", line 424, in check_output
    return run(*popenargs, stdout=PIPE, timeout=timeout, check=True,
  File "/Users/luozisheng/miniconda3/envs/seg/lib/python3.9/subprocess.py", line 505, in run
    with Popen(*popenargs, **kwargs) as process:
  File "/Users/luozisheng/miniconda3/envs/seg/lib/python3.9/subprocess.py", line 951, in __init__
    self._execute_child(args, executable, preexec_fn, close_fds,
  File "/Users/luozisheng/miniconda3/envs/seg/lib/python3.9/subprocess.py", line 1837, in _execute_child
    raise child_exception_type(errno_num, err_msg, err_filename)
FileNotFoundError: [Errno 2] No such file or directory: '/Users/luozisheng/miniconda3/envs/seg/lib/python3.9/site-packages/wandb/bin/apple_gpu_stats'
2025-03-05 11:36:15,296 DEBUG   HandlerThread:64231 [handler.py:handle_request():158] handle_request: internal_messages
2025-03-05 11:36:15,346 DEBUG   HandlerThread:64231 [handler.py:handle_request():158] handle_request: status_report
2025-03-05 11:36:16,299 DEBUG   HandlerThread:64231 [handler.py:handle_request():158] handle_request: internal_messages
2025-03-05 11:36:17,147 ERROR   gpuapple  :64231 [gpu_apple.py:sample():110] GPU stats error: [Errno 2] No such file or directory: '/Users/luozisheng/miniconda3/envs/seg/lib/python3.9/site-packages/wandb/bin/apple_gpu_stats'
Traceback (most recent call last):
  File "/Users/luozisheng/miniconda3/envs/seg/lib/python3.9/site-packages/wandb/sdk/internal/system/assets/gpu_apple.py", line 64, in sample
    subprocess.check_output(command, universal_newlines=True)
  File "/Users/luozisheng/miniconda3/envs/seg/lib/python3.9/subprocess.py", line 424, in check_output
    return run(*popenargs, stdout=PIPE, timeout=timeout, check=True,
  File "/Users/luozisheng/miniconda3/envs/seg/lib/python3.9/subprocess.py", line 505, in run
    with Popen(*popenargs, **kwargs) as process:
  File "/Users/luozisheng/miniconda3/envs/seg/lib/python3.9/subprocess.py", line 951, in __init__
    self._execute_child(args, executable, preexec_fn, close_fds,
  File "/Users/luozisheng/miniconda3/envs/seg/lib/python3.9/subprocess.py", line 1837, in _execute_child
    raise child_exception_type(errno_num, err_msg, err_filename)
FileNotFoundError: [Errno 2] No such file or directory: '/Users/luozisheng/miniconda3/envs/seg/lib/python3.9/site-packages/wandb/bin/apple_gpu_stats'
2025-03-05 11:36:17,302 DEBUG   HandlerThread:64231 [handler.py:handle_request():158] handle_request: internal_messages
2025-03-05 11:36:18,308 DEBUG   HandlerThread:64231 [handler.py:handle_request():158] handle_request: internal_messages
2025-03-05 11:36:19,162 ERROR   gpuapple  :64231 [gpu_apple.py:sample():110] GPU stats error: [Errno 2] No such file or directory: '/Users/luozisheng/miniconda3/envs/seg/lib/python3.9/site-packages/wandb/bin/apple_gpu_stats'
Traceback (most recent call last):
  File "/Users/luozisheng/miniconda3/envs/seg/lib/python3.9/site-packages/wandb/sdk/internal/system/assets/gpu_apple.py", line 64, in sample
    subprocess.check_output(command, universal_newlines=True)
  File "/Users/luozisheng/miniconda3/envs/seg/lib/python3.9/subprocess.py", line 424, in check_output
    return run(*popenargs, stdout=PIPE, timeout=timeout, check=True,
  File "/Users/luozisheng/miniconda3/envs/seg/lib/python3.9/subprocess.py", line 505, in run
    with Popen(*popenargs, **kwargs) as process:
  File "/Users/luozisheng/miniconda3/envs/seg/lib/python3.9/subprocess.py", line 951, in __init__
    self._execute_child(args, executable, preexec_fn, close_fds,
  File "/Users/luozisheng/miniconda3/envs/seg/lib/python3.9/subprocess.py", line 1837, in _execute_child
    raise child_exception_type(errno_num, err_msg, err_filename)
FileNotFoundError: [Errno 2] No such file or directory: '/Users/luozisheng/miniconda3/envs/seg/lib/python3.9/site-packages/wandb/bin/apple_gpu_stats'
2025-03-05 11:36:19,314 DEBUG   HandlerThread:64231 [handler.py:handle_request():158] handle_request: internal_messages
2025-03-05 11:36:20,318 DEBUG   HandlerThread:64231 [handler.py:handle_request():158] handle_request: internal_messages
2025-03-05 11:36:21,176 ERROR   gpuapple  :64231 [gpu_apple.py:sample():110] GPU stats error: [Errno 2] No such file or directory: '/Users/luozisheng/miniconda3/envs/seg/lib/python3.9/site-packages/wandb/bin/apple_gpu_stats'
Traceback (most recent call last):
  File "/Users/luozisheng/miniconda3/envs/seg/lib/python3.9/site-packages/wandb/sdk/internal/system/assets/gpu_apple.py", line 64, in sample
    subprocess.check_output(command, universal_newlines=True)
  File "/Users/luozisheng/miniconda3/envs/seg/lib/python3.9/subprocess.py", line 424, in check_output
    return run(*popenargs, stdout=PIPE, timeout=timeout, check=True,
  File "/Users/luozisheng/miniconda3/envs/seg/lib/python3.9/subprocess.py", line 505, in run
    with Popen(*popenargs, **kwargs) as process:
  File "/Users/luozisheng/miniconda3/envs/seg/lib/python3.9/subprocess.py", line 951, in __init__
    self._execute_child(args, executable, preexec_fn, close_fds,
  File "/Users/luozisheng/miniconda3/envs/seg/lib/python3.9/subprocess.py", line 1837, in _execute_child
    raise child_exception_type(errno_num, err_msg, err_filename)
FileNotFoundError: [Errno 2] No such file or directory: '/Users/luozisheng/miniconda3/envs/seg/lib/python3.9/site-packages/wandb/bin/apple_gpu_stats'
2025-03-05 11:36:21,258 DEBUG   HandlerThread:64231 [handler.py:handle_request():158] handle_request: status_report
2025-03-05 11:36:21,322 DEBUG   HandlerThread:64231 [handler.py:handle_request():158] handle_request: internal_messages
2025-03-05 11:36:22,325 DEBUG   HandlerThread:64231 [handler.py:handle_request():158] handle_request: internal_messages
2025-03-05 11:36:23,191 ERROR   gpuapple  :64231 [gpu_apple.py:sample():110] GPU stats error: [Errno 2] No such file or directory: '/Users/luozisheng/miniconda3/envs/seg/lib/python3.9/site-packages/wandb/bin/apple_gpu_stats'
Traceback (most recent call last):
  File "/Users/luozisheng/miniconda3/envs/seg/lib/python3.9/site-packages/wandb/sdk/internal/system/assets/gpu_apple.py", line 64, in sample
    subprocess.check_output(command, universal_newlines=True)
  File "/Users/luozisheng/miniconda3/envs/seg/lib/python3.9/subprocess.py", line 424, in check_output
    return run(*popenargs, stdout=PIPE, timeout=timeout, check=True,
  File "/Users/luozisheng/miniconda3/envs/seg/lib/python3.9/subprocess.py", line 505, in run
    with Popen(*popenargs, **kwargs) as process:
  File "/Users/luozisheng/miniconda3/envs/seg/lib/python3.9/subprocess.py", line 951, in __init__
    self._execute_child(args, executable, preexec_fn, close_fds,
  File "/Users/luozisheng/miniconda3/envs/seg/lib/python3.9/subprocess.py", line 1837, in _execute_child
    raise child_exception_type(errno_num, err_msg, err_filename)
FileNotFoundError: [Errno 2] No such file or directory: '/Users/luozisheng/miniconda3/envs/seg/lib/python3.9/site-packages/wandb/bin/apple_gpu_stats'
